Workbook

Sheet Tổng hợp
A1: STT | B1: MSSV | C1: Ho và ten | D1: Điểm quá trình | H1: Thi cuối kỳ | J1: Điểm Tổng hợp
D2: Điểm BT | E2: Dự học | F2: Kiểm tra | G2: Tổng điểm quá trình | I2: Điểm HP
A3: 1 | B3: B1909925 | C3: Huynh Huu Khang | D3: ='Điểm bài tập'!D2 -> 0 | E3: 0 | F3: 1 | G3: =IF(E3="Cấm thi","Cấm thi",MIN(SUM(D3:F3),4)) -> 1 | H3: ='Điểm Ktra và điểm thi'!G2 -> 3 | I3: =IF(SUM(E3:H3)>10,10,SUM(E3:H3)) -> 5 | J3: =ROUND(G3+H3,1) -> 4 | L3: =COUNTIF(J3:J94, ">=9") -> 30
A4: 2 | B4: B2204536 | C4: Nguyen Tram Anh | D4: ='Điểm bài tập'!D3 -> 0 | E4: ='Điểm danh'!D3 -> 0.5 | F4: 2 | G4: =IF(E4="Cấm thi","Cấm thi",MIN(SUM(D4:F4),4)) -> 2.5 | H4: ='Điểm Ktra và điểm thi'!G3 -> 5.25 | I4: =IF(SUM(E4:H4)>10,10,SUM(E4:H4)) -> 10 | J4: =ROUND(G4+H4,1) -> 7.8
A5: 3 | B5: B2306513 | C5: Ngo Hung Anh | D5: ='Điểm bài tập'!D4 -> 1 | E5: ='Điểm danh'!D4 -> 0.5 | F5: 2.25 | G5: =IF(E5="Cấm thi","Cấm thi",MIN(SUM(D5:F5),4)) -> 3.75 | H5: ='Điểm Ktra và điểm thi'!G4 -> 4.75 | I5: =IF(SUM(E5:H5)>10,10,SUM(E5:H5)) -> 10 | J5: =ROUND(G5+H5,1) -> 8.5
A6: 4 | B6: B2306514 | C6: Do Hoang Bao | D6: ='Điểm bài tập'!D5 -> 0 | E6: ='Điểm danh'!D5 -> 0.4 | F6: 2.5 | G6: =IF(E6="Cấm thi","Cấm thi",MIN(SUM(D6:F6),4)) -> 2.9 | H6: ='Điểm Ktra và điểm thi'!G5 -> 4.75 | I6: =IF(SUM(E6:H6)>10,10,SUM(E6:H6)) -> 10 | J6: =ROUND(G6+H6,1) -> 7.7
A7: 5 | B7: B2306515 | C7: Tran Ngoc Bao | D7: ='Điểm bài tập'!D6 -> 0 | E7: ='Điểm danh'!D6 -> 0.5 | F7: 2.75 | G7: =IF(E7="Cấm thi","Cấm thi",MIN(SUM(D7:F7),4)) -> 3.25 | H7: ='Điểm Ktra và điểm thi'!G6 -> 5.5 | I7: =IF(SUM(E7:H7)>10,10,SUM(E7:H7)) -> 10 | J7: =ROUND(G7+H7,1) -> 8.8
A8: 6 | B8: B2306516 | C8: Tran Quang Bao | D8: ='Điểm bài tập'!D7 -> 1 | E8: ='Điểm danh'!D7 -> 0.5 | F8: 2.5 | G8: =IF(E8="Cấm thi","Cấm thi",MIN(SUM(D8:F8),4)) -> 4 | H8: ='Điểm Ktra và điểm thi'!G7 -> 5.5 | I8: =IF(SUM(E8:H8)>10,10,SUM(E8:H8)) -> 10 | J8: =ROUND(G8+H8,1) -> 9.5
A9: 7 | B9: B2306517 | C9: Ngo An Binh | D9: ='Điểm bài tập'!D8 -> 0.5 | E9: ='Điểm danh'!D8 -> 0.5 | F9: 2 | G9: =IF(E9="Cấm thi","Cấm thi",MIN(SUM(D9:F9),4)) -> 3 | H9: ='Điểm Ktra và điểm thi'!G8 -> 5.5 | I9: =IF(SUM(E9:H9)>10,10,SUM(E9:H9)) -> 10 | J9: =ROUND(G9+H9,1) -> 8.5
A10: 8 | B10: B2306518 | C10: Nguyen Thanh Binh | D10: ='Điểm bài tập'!D9 -> 1 | E10: ='Điểm danh'!D9 -> 0.5 | F10: 2.5 | G10: =IF(E10="Cấm thi","Cấm thi",MIN(SUM(D10:F10),4)) -> 4 | H10: ='Điểm Ktra và điểm thi'!G9 -> 5.25 | I10: =IF(SUM(E10:H10)>10,10,SUM(E10:H10)) -> 10 | J10: =ROUND(G10+H10,1) -> 9.3
A11: 9 | B11: B2306519 | C11: Truong Vu Binh | D11: ='Điểm bài tập'!D10 -> 0.5 | E11: ='Điểm danh'!D10 -> 0.5 | F11: 2.75 | G11: =IF(E11="Cấm thi","Cấm thi",MIN(SUM(D11:F11),4)) -> 3.75 | H11: ='Điểm Ktra và điểm thi'!G10 -> 3.75 | I11: =IF(SUM(E11:H11)>10,10,SUM(E11:H11)) -> 10 | J11: =ROUND(G11+H11,1) -> 7.5
A12: 10 | B12: B2306521 | C12: Nguyen Chi Cuong | D12: ='Điểm bài tập'!D11 -> 1 | E12: ='Điểm danh'!D11 -> 0.5 | F12: 2 | G12: =IF(E12="Cấm thi","Cấm thi",MIN(SUM(D12:F12),4)) -> 3.5 | H12: ='Điểm Ktra và điểm thi'!G11 -> 4.25 | I12: =IF(SUM(E12:H12)>10,10,SUM(E12:H12)) -> 10 | J12: =ROUND(G12+H12,1) -> 7.8
A13: 11 | B13: B2306522 | C13: Doan Cong Danh | D13: ='Điểm bài tập'!D12 -> 1 | E13: ='Điểm danh'!D12 -> 0.5 | F13: 2 | G13: =IF(E13="Cấm thi","Cấm thi",MIN(SUM(D13:F13),4)) -> 3.5 | H13: ='Điểm Ktra và điểm thi'!G12 -> 6 | I13: =IF(SUM(E13:H13)>10,10,SUM(E13:H13)) -> 10 | J13: =ROUND(G13+H13,1) -> 9.5
A14: 12 | B14: B2306523 | C14: Doan Trung Dan | D14: ='Điểm bài tập'!D13 -> 0.5 | E14: ='Điểm danh'!D13 -> 0.5 | F14: 1.75 | G14: =IF(E14="Cấm thi","Cấm thi",MIN(SUM(D14:F14),4)) -> 2.75 | H14: ='Điểm Ktra và điểm thi'!G13 -> 5.75 | I14: =IF(SUM(E14:H14)>10,10,SUM(E14:H14)) -> 10 | J14: =ROUND(G14+H14,1) -> 8.5
A15: 13 | B15: B2306524 | C15: Mai Vu Duy | D15: ='Điểm bài tập'!D14 -> 1 | E15: ='Điểm danh'!D14 -> 0.5 | F15: 2.75 | G15: =IF(E15="Cấm thi","Cấm thi",MIN(SUM(D15:F15),4)) -> 4 | H15: ='Điểm Ktra và điểm thi'!G14 -> 5.5 | I15: =IF(SUM(E15:H15)>10,10,SUM(E15:H15)) -> 10 | J15: =ROUND(G15+H15,1) -> 9.5
... A26: 24 | B26: B2306536 | C26: Tram Gia Huy | D26: ='Điểm bài tập'!D25 -> 0 | E26: ='Điểm danh'!D25 -> 0.2 | F26: 1.25 | G26: =IF(E26="Cấm thi","Cấm thi",MIN(SUM(D26:F26),4)) -> 1.45 | H26: ='Điểm Ktra và điểm thi'!G25 -> 4 | I26: =IF(SUM(E26:H26)>10,10,SUM(E26:H26)) -> 6.9 | J26: =ROUND(G26+H26,1) -> 5.5
A27: 25 | B27: B2306537 | C27: Ly Pho Huynh | D27: ='Điểm bài tập'!D26 -> 0 | E27: 0 | F27: 1.25 | G27: =IF(E27="Cấm thi","Cấm thi",MIN(SUM(D27:F27),4)) -> 1.25 | H27: ='Điểm Ktra và điểm thi'!G26 -> 1.25 | I27: =IF(SUM(E27:H27)>10,10,SUM(E27:H27)) -> 3.75 | J27: =ROUND(G27+H27,1) -> 2.5
A28: 26 | B28: B2306538 | C28: Nguyen Thi Nhu Huynh | D28: ='Điểm bài tập'!D27 -> 0 | E28: ='Điểm danh'!D27 -> 0.4 | F28: 2 | G28: =IF(E28="Cấm thi","Cấm thi",MIN(SUM(D28:F28),4)) -> 2.4 | H28: ='Điểm Ktra và điểm thi'!G27 -> 3.5 | I28: =IF(SUM(E28:H28)>10,10,SUM(E28:H28)) -> 8.3 | J28: =ROUND(G28+H28,1) -> 5.9
A29: 27 | B29: B2306539 | C29: Nguyen Phi Hung | D29: ='Điểm bài tập'!D28 -> 0 | E29: ='Điểm danh'!D28 -> 0.3 | F29: 1.25 | G29: =IF(E29="Cấm thi","Cấm thi",MIN(SUM(D29:F29),4)) -> 1.55 | H29: ='Điểm Ktra và điểm thi'!G28 -> 3.25 | I29: =IF(SUM(E29:H29)>10,10,SUM(E29:H29)) -> 6.35 | J29: =ROUND(G29+H29,1) -> 4.8
A30: 28 | B30: B2306540 | C30: Nguyen Hoang Khang | D30: ='Điểm bài tập'!D29 -> 0 | E30: ='Điểm danh'!D29 -> 0.5 | F30: 2.5 | G30: =IF(E30="Cấm thi","Cấm thi",MIN(SUM(D30:F30),4)) -> 3 | H30: ='Điểm Ktra và điểm thi'!G29 -> 5.25 | I30: =IF(SUM(E30:H30)>10,10,SUM(E30:H30)) -> 10 | J30: =ROUND(G30+H30,1) -> 8.3
A31: 29 | B31: B2306541 | C31: Nguyen Truong Vi Khang | D31: ='Điểm bài tập'!D30 -> 0 | E31: ='Điểm danh'!D30 -> 0.5 | F31: 1 | G31: =IF(E31="Cấm thi","Cấm thi",MIN(SUM(D31:F31),4)) -> 1.5 | H31: ='Điểm Ktra và điểm thi'!G30 -> 4 | I31: =IF(SUM(E31:H31)>10,10,SUM(E31:H31)) -> 7 | J31: =ROUND(G31+H31,1) -> 5.5
A32: 30 | B32: B2306542 | C32: Phan Thanh Khang | D32: ='Điểm bài tập'!D31 -> 0.5 | E32: ='Điểm danh'!D31 -> 0.5 | F32: 0.75 | G32: =IF(E32="Cấm thi","Cấm thi",MIN(SUM(D32:F32),4)) -> 1.75 | H32: ='Điểm Ktra và điểm thi'!G31 -> 4.5 | I32: =IF(SUM(E32:H32)>10,10,SUM(E32:H32)) -> 7.5 | J32: =ROUND(G32+H32,1) -> 6.3
A33: 31 | B33: B2306543 | C33: Tieu Tuan Khang | D33: ='Điểm bài tập'!D32 -> 0 | E33: ='Điểm danh'!D32 -> 0.5 | F33: 0 | G33: =IF(E33="Cấm thi","Cấm thi",MIN(SUM(D33:F33),4)) -> 0.5 | H33: ='Điểm Ktra và điểm thi'!G32 -> 3.75 | I33: =IF(SUM(E33:H33)>10,10,SUM(E33:H33)) -> 4.75
A34: 32 | B34: B2306544 | C34: Vo An Khang | D34: ='Điểm bài tập'!D33 -> 0.5 | E34: ='Điểm danh'!D33 -> 0.5 | F34: 3 | G34: =IF(E34="Cấm thi","Cấm thi",MIN(SUM(D34:F34),4)) -> 4 | H34: ='Điểm Ktra và điểm thi'!G33 -> 6 | I34: =IF(SUM(E34:H34)>10,10,SUM(E34:H34)) -> 10 | J34: =ROUND(G34+H34,1) -> 10
A35: 33 | B35: B2306545 | C35: Vo Minh Khang | D35: ='Điểm bài tập'!D34 -> 0 | E35: ='Điểm danh'!D34 -> 0.4 | F35: 1.25 | G35: =IF(E35="Cấm thi","Cấm thi",MIN(SUM(D35:F35),4)) -> 1.65 | H35: ='Điểm Ktra và điểm thi'!G34 -> 3 | I35: =IF(SUM(E35:H35)>10,10,SUM(E35:H35)) -> 6.3 | J35: =ROUND(G35+H35,1) -> 4.7
A36: 34 | B36: B2306546 | C36: Tran Tuan Khanh | D36: ='Điểm bài tập'!D35 -> 0.5 | E36: ='Điểm danh'!D35 -> 0.5 | F36: 1.75 | G36: =IF(E36="Cấm thi","Cấm thi",MIN(SUM(D36:F36),4)) -> 2.75 | H36: ='Điểm Ktra và điểm thi'!G35 -> 2.5 | I36: =IF(SUM(E36:H36)>10,10,SUM(E36:H36)) -> 7.5 | J36: =ROUND(G36+H36,1) -> 5.3
A37: 35 | B37: B2306547 | C37: Vo Thai Hoang Khanh | D37: ='Điểm bài tập'!D36 -> 1 | E37: ='Điểm danh'!D36 -> 0.5 | F37: 2 | G37: =IF(E37="Cấm thi","Cấm thi",MIN(SUM(D37:F37),4)) -> 3.5 | H37: ='Điểm Ktra và điểm thi'!G36 -> 5.5 | I37: =IF(SUM(E37:H37)>10,10,SUM(E37:H37)) -> 10 | J37: =ROUND(G37+H37,1) -> 9
A38: 36 | B38: B2306548 | C38: Tran Thai Khai | D38: ='Điểm bài tập'!D37 -> 0.5 | E38: ='Điểm danh'!D37 -> 0.5 | F38: 2 | G38: =IF(E38="Cấm thi","Cấm thi",MIN(SUM(D38:F38),4)) -> 3 | H38: ='Điểm Ktra và điểm thi'!G37 -> 5 | I38: =IF(SUM(E38:H38)>10,10,SUM(E38:H38)) -> 10 | J38: =ROUND(G38+H38,1) -> 8
A39: 37 | B39: B2306549 | C39: Phung Dang Khoa | D39: ='Điểm bài tập'!D38 -> 0.5 | E39: ='Điểm danh'!D38 -> 0.5 | F39: 1 | G39: =IF(E39="Cấm thi","Cấm thi",MIN(SUM(D39:F39),4)) -> 2 | H39: ='Điểm Ktra và điểm thi'!G38 -> 3.75 | I39: =IF(SUM(E39:H39)>10,10,SUM(E39:H39)) -> 7.25 | J39: =ROUND(G39+H39,1) -> 5.8
A40: 38 | B40: B2306550 | C40: Tran Pham Dang Khoa | D40: ='Điểm bài tập'!D39 -> 1 | E40: ='Điểm danh'!D39 -> 0.5 | F40: 1.75 | G40: =IF(E40="Cấm thi","Cấm thi",MIN(SUM(D40:F40),4)) -> 3.25 | H40: ='Điểm Ktra và điểm thi'!G39 -> 5.75 | I40: =IF(SUM(E40:H40)>10,10,SUM(E40:H40)) -> 10 | J40: =ROUND(G40+H40,1) -> 9
A41: 39 | B41: B2306551 | C41: Nguyen Dang Khoi | D41: ='Điểm bài tập'!D40 -> 1 | E41: ='Điểm danh'!D40 -> 0.5 | F41: 1 | G41: =IF(E41="Cấm thi","Cấm thi",MIN(SUM(D41:F41),4)) -> 2.5 | H41: ='Điểm Ktra và điểm thi'!G40 -> 5.75 | I41: =IF(SUM(E41:H41)>10,10,SUM(E41:H41)) -> 9.75 | J41: =ROUND(G41+H41,1) -> 8.3
A42: 40 | B42: B2306552 | C42: Tran Trung Kien | D42: ='Điểm bài tập'!D41 -> 1 | E42: ='Điểm danh'!D41 -> 0.5 | F42: 2.5 | G42: =IF(E42="Cấm thi","Cấm thi",MIN(SUM(D42:F42),4)) -> 4 | H42: ='Điểm Ktra và điểm thi'!G41 -> 5.25 | I42: =IF(SUM(E42:H42)>10,10,SUM(E42:H42)) -> 10 | J42: =ROUND(G42+H42,1) -> 9.3
A43: 41 | B43: B2306553 | C43: Dang Quang Ky | D43: ='Điểm bài tập'!D42 -> 1 | E43: ='Điểm danh'!D42 -> 0.4 | F43: 1 | G43: =IF(E43="Cấm thi","Cấm thi",MIN(SUM(D43:F43),4)) -> 2.4 | H43: ='Điểm Ktra và điểm thi'!G42 -> 5.75 | I43: =IF(SUM(E43:H43)>10,10,SUM(E43:H43)) -> 9.55 | J43: =ROUND(G43+H43,1) -> 8.2
A44: 42 | B44: B2306554 | C44: Tran Thi Yen Linh | D44: ='Điểm bài tập'!D43 -> 1 | E44: ='Điểm danh'!D43 -> 0.5 | F44: 1.25 | G44: =IF(E44="Cấm thi","Cấm thi",MIN(SUM(D44:F44),4)) -> 2.75 | H44: ='Điểm Ktra và điểm thi'!G43 -> 3.75 | I44: =IF(SUM(E44:H44)>10,10,SUM(E44:H44)) -> 8.25 | J44: =ROUND(G44+H44,1) -> 6.5
A45: 43 | B45: B2306555 | C45: Chung Tan Loi | D45: ='Điểm bài tập'!D44 -> 0.5 | E45: ='Điểm danh'!D44 -> 0.5 | F45: 2.5 | G45: =IF(E45="Cấm thi","Cấm thi",MIN(SUM(D45:F45),4)) -> 3.5 | H45: ='Điểm Ktra và điểm thi'!G44 -> 5.5 | I45: =IF(SUM(E45:H45)>10,10,SUM(E45:H45)) -> 10 | J45: =ROUND(G45+H45,1) -> 9
... A47: 45 | B47: B2306557 | C47: Le Huu Luong | D47: ='Điểm bài tập'!D46 -> 1 | E47: ='Điểm danh'!D46 -> 0.5 | F47: 2.25 | G47: =IF(E47="Cấm thi","Cấm thi",MIN(SUM(D47:F47),4)) -> 3.75 | H47: ='Điểm Ktra và điểm thi'!G46 -> 5.5 | I47: =IF(SUM(E47:H47)>10,10,SUM(E47:H47)) -> 10 | J47: =ROUND(G47+H47,1) -> 9.3
A48: 46 | B48: B2306558 | C48: Cao Khanh Minh | D48: ='Điểm bài tập'!D47 -> 0 | E48: 0 | F48: 2 | G48: =IF(E48="Cấm thi","Cấm thi",MIN(SUM(D48:F48),4)) -> 2 | H48: ='Điểm Ktra và điểm thi'!G47 -> 1.25 | I48: =IF(SUM(E48:H48)>10,10,SUM(E48:H48)) -> 5.25 | J48: =ROUND(G48+H48,1) -> 3.3
A49: 47 | B49: B2306559 | C49: Nguyen Thi Nhu Mi | D49: ='Điểm bài tập'!D48 -> 1 | E49: ='Điểm danh'!D48 -> 0.5 | F49: 2.25 | G49: =IF(E49="Cấm thi","Cấm thi",MIN(SUM(D49:F49),4)) -> 3.75 | H49: ='Điểm Ktra và điểm thi'!G48 -> 5.75 | I49: =IF(SUM(E49:H49)>10,10,SUM(E49:H49)) -> 10 | J49: =ROUND(G49+H49,1) -> 9.5
A50: 48 | B50: B2306560 | C50: Nguyen Thi Diem My | D50: ='Điểm bài tập'!D49 -> 1 | E50: ='Điểm danh'!D49 -> 0.5 | F50: 2.75 | G50: =IF(E50="Cấm thi","Cấm thi",MIN(SUM(D50:F50),4)) -> 4 | H50: ='Điểm Ktra và điểm thi'!G49 -> 5.5 | I50: =IF(SUM(E50:H50)>10,10,SUM(E50:H50)) -> 10 | J50: =ROUND(G50+H50,1) -> 9.5
A51: 49 | B51: B2306561 | C51: Huynh Chi Nghia | D51: ='Điểm bài tập'!D50 -> 1 | E51: ='Điểm danh'!D50 -> 0.4 | F51: 2.5 | G51: =IF(E51="Cấm thi","Cấm thi",MIN(SUM(D51:F51),4)) -> 3.9 | H51: ='Điểm Ktra và điểm thi'!G50 -> 5.75 | I51: =IF(SUM(E51:H51)>10,10,SUM(E51:H51)) -> 10 | J51: =ROUND(G51+H51,1) -> 9.7
...

Sheet Điểm Ktra và điểm thi
A1: STT | B1: Ma sinh vien | C1: Ho và ten | D1: Số câu đúng | E1: Điểm | F1: Số câu đúng | G1: Điểm
A2: 1 | B2: B1909925 | C2: Huynh Huu Khang | D2: 4 | E2: 1 | F2: 12 | G2: =F2/4 -> 3
A3: 2 | B3: B2204536 | C3: Nguyen Tram Anh | D3: 8 | E3: 2 | F3: 21 | G3: =F3/4 -> 5.25
A4: 3 | B4: B2306513 | C4: Ngo Hung Anh | D4: 9 | E4: 2.25 | F4: 19 | G4: =F4/4 -> 4.75
A5: 4 | B5: B2306514 | C5: Do Hoang Bao | D5: 10 | E5: 2.5 | F5: 19 | G5: =F5/4 -> 4.75
A6: 5 | B6: B2306515 | C6: Tran Ngoc Bao | D6: 11 | E6: 2.75 | F6: 22 | G6: =F6/4 -> 5.5
A7: 6 | B7: B2306516 | C7: Tran Quang Bao | D7: 10 | E7: 2.5 | F7: 22 | G7: =F7/4 -> 5.5
A8: 7 | B8: B2306517 | C8: Ngo An Binh | D8: 8 | E8: 2 | F8: 22 | G8: =F8/4 -> 5.5 | K8: =COUNTIF(G2:G93, "> 9") -> 1
A9: 8 | B9: B2306518 | C9: Nguyen Thanh Binh | D9: 10 | E9: 2.5 | F9: 21 | G9: =F9/4 -> 5.25
A10: 9 | B10: B2306519 | C10: Truong Vu Binh | D10: 11 | E10: 2.75 | F10: 15 | G10: =F10/4 -> 3.75
A11: 10 | B11: B2306521 | C11: Nguyen Chi Cuong | D11: 8 | E11: 2 | F11: 17 | G11: =F11/4 -> 4.25
A12: 11 | B12: B2306522 | C12: Doan Cong Danh | D12: 8 | E12: 2 | F12: 24 | G12: =F12/4 -> 6
A13: 12 | B13: B2306523 | C13: Doan Trung Dan | D13: 7 | E13: 1.75 | F13: 23 | G13: =F13/4 -> 5.75
A14: 13 | B14: B2306524 | C14: Mai Vu Duy | D14: 11 | E14: 2.75 | F14: 22 | G14: =F14/4 -> 5.5
A15: 14 | B15: B2306525 | C15: Ly Phuoc Dat | D15: 10 | E15: 2.5 | F15: 23 | G15: =F15/4 -> 5.75
A16: 15 | B16: B2306526 | C16: Tran Do Quoc Dat | D16: 4 | E16: 1 | F16: 16 | G16: =F16/4 -> 4
A17: 16 | B17: B2306527 | C17: Ho Quang Truong Giang | D17: 11 | E17: 2.75 | F17: 22 | G17: =F17/4 -> 5.5
A18: 17 | B18: B2306528 | C18: Truong Chi Hao | D18: 11 | E18: 2.75 | F18: 24 | G18: =F18/4 -> 6
A19: 18 | B19: B2306529 | C19: Vo Huynh Thanh Ha | D19: 8 | E19: 2 | F19: 10 | G19: =F19/4 -> 2.5
A20: 19 | B20: B2306530 | C20: Pham Phan Dung Hanh | D20: 7 | E20: 1.75 | F20: 21 | G20: =F20/4 -> 5.25
... A31: 30 | B31: B2306542 | C31: Phan Thanh Khang | D31: 3 | E31: 0.75 | F31: 18 | G31: =F31/4 -> 4.5
A32: 31 | B32: B2306543 | C32: Tieu Tuan Khang | E32: 0 | F32: 15 | G32: =F32/4 -> 3.75
A33: 32 | B33: B2306544 | C33: Vo An Khang | D33: 12 | E33: 3 | F33: 24 | G33: =F33/4 -> 6
A34: 33 | B34: B2306545 | C34: Vo Minh Khang | D34: 5 | E34: 1.25 | F34: 12 | G34: =F34/4 -> 3
A35: 34 | B35: B2306546 | C35: Tran Tuan Khanh | D35: 7 | E35: 1.75 | F35: 10 | G35: =F35/4 -> 2.5
A36: 35 | B36: B2306547 | C36: Vo Thai Hoang Khanh | D36: 8 | E36: 2 | F36: 22 | G36: =F36/4 -> 5.5
A37: 36 | B37: B2306548 | C37: Tran Thai Khai | D37: 8 | E37: 2 | F37: 20 | G37: =F37/4 -> 5
A38: 37 | B38: B2306549 | C38: Phung Dang Khoa | D38: 4 | E38: 1 | F38: 15 | G38: =F38/4 -> 3.75
A39: 38 | B39: B2306550 | C39: Tran Pham Dang Khoa | D39: 7 | E39: 1.75 | F39: 23 | G39: =F39/4 -> 5.75
A40: 39 | B40: B2306551 | C40: Nguyen Dang Khoi | D40: 4 | E40: 1 | F40: 23 | G40: =F40/4 -> 5.75
A41: 40 | B41: B2306552 | C41: Tran Trung Kien | D41: 10 | E41: 2.5 | F41: 21 | G41: =F41/4 -> 5.25
A42: 41 | B42: B2306553 | C42: Dang Quang Ky | D42: 4 | E42: 1 | F42: 23 | G42: =F42/4 -> 5.75
A43: 42 | B43: B2306554 | C43: Tran Thi Yen Linh | D43: 5 | E43: 1.25 | F43: 15 | G43: =F43/4 -> 3.75
A44: 43 | B44: B2306555 | C44: Chung Tan Loi | D44: 10 | E44: 2.5 | F44: 22 | G44: =F44/4 -> 5.5
... A93: 92 | B93: B2306608 | C93: Nguyen Thi Nhu Y | D93: 12 | E93: 3 | F93: 22 | G93: =F93/4 -> 5.5

Sheet Điểm danh
A1: STT | B1: Ma sinh vien | C1: Ho và ten | D1: Dự học | E1: Số buổi Vắng | F1: 45197 | G1: 45201 | H1: 45202 | I1: 45204 | J1: 45208 | K1: 45205 | L1: 45216 | M1: 45218 | N1: 45222 | O1: 45223 | P1: 45225
A2: 1 | B2: B1909925 | C2: Huynh Huu Khang | D2: =IF(E2=0,0.5,IF(E2=1,0.4,IF(E2=2,0.3,IF(E2=3,0.2,"Cấm thi")))) -> Cấm thi | E2: =COUNTIF(F2:P2,0) -> 4 | F2: 0 | G2: 0 | H2: 0 | I2: 1 | J2: 1 | K2: 1 | L2: 1 | M2: 1 | N2: 1 | O2: 1 | P2: 0
A3: 2 | B3: B2204536 | C3: Nguyen Tram Anh | D3: =IF(E3=0,0.5,IF(E3=1,0.4,IF(E3=2,0.3,IF(E3=3,0.2,"Cấm thi")))) -> 0.5 | E3: =COUNTIF(F3:P3,0) -> 0 | F3: 1 | G3: 1 | H3: 1 | I3: 1 | J3: 1 | K3: 1 | L3: 1 | M3: 1 | N3: 1 | O3: 1 | P3: 1
A4: 3 | B4: B2306513 | C4: Ngo Hung Anh | D4: =IF(E4=0,0.5,IF(E4=1,0.4,IF(E4=2,0.3,IF(E4=3,0.2,"Cấm thi")))) -> 0.5 | E4: =COUNTIF(F4:P4,0) -> 0 | F4: 1 | G4: 1 | H4: 1 | I4: 1 | J4: 1 | K4: 1 | L4: 1 | M4: 1 | N4: 1 | O4: 1 | P4: 1
A5: 4 | B5: B2306514 | C5: Do Hoang Bao | D5: =IF(E5=0,0.5,IF(E5=1,0.4,IF(E5=2,0.3,IF(E5=3,0.2,"Cấm thi")))) -> 0.4 | E5: =COUNTIF(F5:P5,0) -> 1 | F5: 1 | G5: 1 | H5: 1 | I5: 1 | J5: 1 | K5: 1 | L5: 1 | M5: 1 | N5: 0 | O5: 1 | P5: 1
A6: 5 | B6: B2306515 | C6: Tran Ngoc Bao | D6: =IF(E6=0,0.5,IF(E6=1,0.4,IF(E6=2,0.3,IF(E6=3,0.2,"Cấm thi")))) -> 0.5 | E6: =COUNTIF(F6:P6,0) -> 0 | F6: 1 | G6: 1 | H6: 1 | I6: 1 | J6: 1 | K6: 1 | L6: 1 | M6: 1 | N6: 1 | O6: 1 | P6: 1
A7: 6 | B7: B2306516 | C7: Tran Quang Bao | D7: =IF(E7=0,0.5,IF(E7=1,0.4,IF(E7=2,0.3,IF(E7=3,0.2,"Cấm thi")))) -> 0.5 | E7: =COUNTIF(F7:P7,0) -> 0 | F7: 1 | G7: 1 | H7: 1 | I7: 1 | J7: 1 | K7: 1 | L7: 1 | M7: 1 | N7: 1 | O7: 1 | P7: 1
A8: 7 | B8: B2306517 | C8: Ngo An Binh | D8: =IF(E8=0,0.5,IF(E8=1,0.4,IF(E8=2,0.3,IF(E8=3,0.2,"Cấm thi")))) -> 0.5 | E8: =COUNTIF(F8:P8,0) -> 0 | F8: 1 | G8: 1 | H8: 1 | I8: 1 | J8: 1 | K8: 1 | L8: 1 | M8: 1 | N8: 1 | O8: 1 | P8: 1
A9: 8 | B9: B2306518 | C9: Nguyen Thanh Binh | D9: =IF(E9=0,0.5,IF(E9=1,0.4,IF(E9=2,0.3,IF(E9=3,0.2,"Cấm thi")))) -> 0.5 | E9: =COUNTIF(F9:P9,0) -> 0 | F9: 1 | G9: 1 | H9: 1 | I9: 1 | J9: 1 | K9: 1 | L9: 1 | M9: 1 | N9: 1 | O9: 1 | P9: 1
A10: 9 | B10: B2306519 | C10: Truong Vu Binh | D10: =IF(E10=0,0.5,IF(E10=1,0.4,IF(E10=2,0.3,IF(E10=3,0.2,"Cấm thi")))) -> 0.5 | E10: =COUNTIF(F10:P10,0) -> 0 | F10: 1 | G10: 1 | H10: 1 | I10: 1 | J10: 1 | K10: 1 | L10: 1 | M10: 1 | N10: 1 | O10: 1 | P10: 1
A11: 10 | B11: B2306521 | C11: Nguyen Chi Cuong | D11: =IF(E11=0,0.5,IF(E11=1,0.4,IF(E11=2,0.3,IF(E11=3,0.2,"Cấm thi")))) -> 0.5 | E11: =COUNTIF(F11:P11,0) -> 0 | F11: 1 | G11: 1 | H11: 1 | I11: 1 | J11: 1 | K11: 1 | L11: 1 | M11: 1 | N11: 1 | O11: 1 | P11: 1
A12: 11 | B12: B2306522 | C12: Doan Cong Danh | D12: =IF(E12=0,0.5,IF(E12=1,0.4,IF(E12=2,0.3,IF(E12=3,0.2,"Cấm thi")))) -> 0.5 | E12: =COUNTIF(F12:P12,0) -> 0 | F12: 1 | G12: 1 | H12: 1 | I12: 1 | J12: 1 | K12: 1 | L12: 1 | M12: 1 | N12: 1 | O12: 1 | P12: 1
A13: 12 | B13: B2306523 | C13: Doan Trung Dan | D13: =IF(E13=0,0.5,IF(E13=1,0.4,IF(E13=2,0.3,IF(E13=3,0.2,"Cấm thi")))) -> 0.5 | E13: =COUNTIF(F13:P13,0) -> 0 | F13: 1 | G13: 1 | H13: 1 | I13: 1 | J13: 1 | K13: 1 | L13: 1 | M13: 1 | N13: 1 | O13: 1 | P13: 1
... A93: 92 | B93: B2306608 | C93: Nguyen Thi Nhu Y | D93: =IF(E93=0,0.5,IF(E93=1,0.4,IF(E93=2,0.3,IF(E93=3,0.2,"Cấm thi")))) -> 0.5 | E93: =COUNTIF(F93:P93,0) -> 0 | F93: 1 | G93: 1 | H93: 1 | I93: 1 | J93: 1 | K93: 1 | L93: 1 | M93: 1 | N93: 1 | O93: 1 | P93: 1

Sheet Điểm bài tập
A1: STT | B1: MSSV | C1: Ho và ten | D1: Điểm BT | E1: 45194 | F1: 45195 | G1: 45196 | H1: 45197 | I1: 45202 | J1: 45215 | K1: 45216 | L1: 45218 | M1: 45222 | N1: 45223
A2: 1 | B2: B1909925 | C2: Huynh Huu Khang | D2: =MIN(SUM(E2:N2),1) -> 0
A3: 2 | B3: B2204536 | C3: Nguyen Tram Anh | D3: =MIN(SUM(E3:N3),1) -> 0
A4: 3 | B4: B2306513 | C4: Ngo Hung Anh | D4: =MIN(SUM(E4:N4),1) -> 1 | F4: 0.5 | H4: 0.5 | I4: 0.5 | K4: 0.5 | L4: 0.5
A5: 4 | B5: B2306514 | C5: Do Hoang Bao | D5: =MIN(SUM(E5:N5),1) -> 0
A6: 5 | B6: B2306515 | C6: Tran Ngoc Bao | D6: =MIN(SUM(E6:N6),1) -> 0
A7: 6 | B7: B2306516 | C7: Tran Quang Bao | D7: =MIN(SUM(E7:N7),1) -> 1 | J7: 0.5 | K7: 0.5 | L7: 0.5
A8: 7 | B8: B2306517 | C8: Ngo An Binh | D8: =MIN(SUM(E8:N8),1) -> 0.5 | F8: 0.5
A9: 8 | B9: B2306518 | C9: Nguyen Thanh Binh | D9: =MIN(SUM(E9:N9),1) -> 1 | E9: 0.5 | F9: 0.5 | H9: 0.5
A10: 9 | B10: B2306519 | C10: Truong Vu Binh | D10: =MIN(SUM(E10:N10),1) -> 0.5 | K10: 0.5
A11: 10 | B11: B2306521 | C11: Nguyen Chi Cuong | D11: =MIN(SUM(E11:N11),1) -> 1 | E11: 0.5 | G11: 0.5 | I11: 0.5 | K11: 0.5
A12: 11 | B12: B2306522 | C12: Doan Cong Danh | D12: =MIN(SUM(E12:N12),1) -> 1 | I12: 0.5 | J12: 0.5 | K12: 0.5 | L12: 0.5
A13: 12 | B13: B2306523 | C13: Doan Trung Dan | D13: =MIN(SUM(E13:N13),1) -> 0.5 | K13: 0.5
A14: 13 | B14: B2306524 | C14: Mai Vu Duy | D14: =MIN(SUM(E14:N14),1) -> 1 | E14: 0.5 | F14: 0.5 | K14: 0.5 | M14: 1
A15: 14 | B15: B2306525 | C15: Ly Phuoc Dat | D15: =MIN(SUM(E15:N15),1) -> 1 | L15: 0.5 | M15: 1
A16: 15 | B16: B2306526 | C16: Tran Do Quoc Dat | D16: =MIN(SUM(E16:N16),1) -> 1 | E16: 0.5 | F16: 0.5 | H16: 0.5 | K16: 0.5
A17: 16 | B17: B2306527 | C17: Ho Quang Truong Giang | D17: =MIN(SUM(E17:N17),1) -> 0.5 | E17: 0.5
A18: 17 | B18: B2306528 | C18: Truong Chi Hao | D18: =MIN(SUM(E18:N18),1) -> 1 | E18: 0.5 | F18: 0.5 | H18: 0.5 | I18: 0.5 | L18: 0.5
A19: 18 | B19: B2306529 | C19: Vo Huynh Thanh Ha | D19: =MIN(SUM(E19:N19),1) -> 0
A20: 19 | B20: B2306530 | C20: Pham Phan Dung Hanh | D20: =MIN(SUM(E20:N20),1) -> 1 | F20: 0.5 | I20: 0.5 | K20: 0.5 | L20: 0.5
A21: 20 | B21: B2306531 | C21: Nguyen Thi Ngoc Han | D21: =MIN(SUM(E21:N21),1) -> 0
A22: 21 | B22: B2306533 | C22: Nguyen Thai Hoa | D22: =MIN(SUM(E22:N22),1) -> 0
A23: 22 | B23: B2306534 | C23: Ho Gia Huy | D23: =MIN(SUM(E23:N23),1) -> 1 | F23: 0.5 | M23: 1
A24: 23 | B24: B2306535 | C24: Nguyen Quang Huy | D24: =MIN(SUM(E24:N24),1) -> 0
A25: 24 | B25: B2306536 | C25: Tram Gia Huy | D25: =MIN(SUM(E25:N25),1) -> 0
A26: 25 | B26: B2306537 | C26: Ly Pho Huynh | D26: =MIN(SUM(E26:N26),1) -> 0
A27: 26 | B27: B2306538 | C27: Nguyen Thi Nhu Huynh | D27: =MIN(SUM(E27:N27),1) -> 0
A28: 27 | B28: B2306539 | C28: Nguyen Phi Hung | D28: =MIN(SUM(E28:N28),1) -> 0
A29: 28 | B29: B2306540 | C29: Nguyen Hoang Khang | D29: =MIN(SUM(E29:N29),1) -> 0
A30: 29 | B30: B2306541 | C30: Nguyen Truong Vi Khang | D30: =MIN(SUM(E30:N30),1) -> 0
A31: 30 | B31: B2306542 | C31: Phan Thanh Khang | D31: =MIN(SUM(E31:N31),1) -> 0.5 | J31: 0.5
A32: 31 | B32: B2306543 | C32: Tieu Tuan Khang | D32: =MIN(SUM(E32:N32),1) -> 0
A33: 32 | B33: B2306544 | C33: Vo An Khang | D33: =MIN(SUM(E33:N33),1) -> 0.5 | F33: 0.5
A34: 33 | B34: B2306545 | C34: Vo Minh Khang | D34: =MIN(SUM(E34:N34),1) -> 0
A35: 34 | B35: B2306546 | C35: Tran Tuan Khanh | D35: =MIN(SUM(E35:N35),1) -> 0.5 | I35: 0.5
A36: 35 | B36: B2306547 | C36: Vo Thai Hoang Khanh | D36: =MIN(SUM(E36:N36),1) -> 1 | I36: 0.5 | M36: 1
A37: 36 | B37: B2306548 | C37: Tran Thai Khai | D37: =MIN(SUM(E37:N37),1) -> 0.5 | F37: 0.5
A38: 37 | B38: B2306549 | C38: Phung Dang Khoa | D38: =MIN(SUM(E38:N38),1) -> 0.5 | H38: 0.5
A39: 38 | B39: B2306550 | C39: Tran Pham Dang Khoa | D39: =MIN(SUM(E39:N39),1) -> 1 | F39: 0.5 | I39: 0.5 | J39: 0.5
A40: 39 | B40: B2306551 | C40: Nguyen Dang Khoi | D40: =MIN(SUM(E40:N40),1) -> 1 | F40: 0.5 | J40: 0.5 | L40: 0.5
...
